Workbook

Sheet Both_Shift_Roster
G1: ="Wk-"&WEEKNUM(DAY(G2)) -> Wk-1 | H1: ="Wk-"&WEEKNUM(DAY(H2)) -> Wk-1 | I1: ="Wk-"&WEEKNUM(DAY(I2)) -> Wk-1 | J1: ="Wk-"&WEEKNUM(DAY(J2)) -> Wk-1 | K1: ="Wk-"&WEEKNUM(DAY(K2)) -> Wk-1 | L1: ="Wk-"&WEEKNUM(DAY(L2)) -> Wk-1 | M1: ="Wk-"&WEEKNUM(DAY(M2)) -> Wk-1 | S1: ="Wk-"&WEEKNUM(DAY(S2)) -> Wk-2 | T1: ="Wk-"&WEEKNUM(DAY(T2)) -> Wk-2 | U1: ="Wk-"&WEEKNUM(DAY(U2)) -> Wk-2 | V1: ="Wk-"&WEEKNUM(DAY(V2)) -> Wk-2 | W1: ="Wk-"&WEEKNUM(DAY(W2)) -> Wk-2 | X1: ="Wk-"&WEEKNUM(DAY(X2)) -> Wk-2 | Y1: ="Wk-"&WEEKNUM(DAY(Y2)) -> Wk-2 | AE1: ="Wk-"&WEEKNUM(DAY(AE2)) -> Wk-3 | AF1: ="Wk-"&WEEKNUM(DAY(AF2)) -> Wk-3 | AG1: ="Wk-"&WEEKNUM(DAY(AG2)) -> Wk-3 | AH1: ="Wk-"&WEEKNUM(DAY(AH2)) -> Wk-3 | AI1: ="Wk-"&WEEKNUM(DAY(AI2)) -> Wk-3 | AJ1: ="Wk-"&WEEKNUM(DAY(AJ2)) -> Wk-3 | AK1: ="Wk-"&WEEKNUM(DAY(AK2)) -> Wk-3 | AQ1: ="Wk-"&WEEKNUM(DAY(AQ2)) -> Wk-4 | AR1: ="Wk-"&WEEKNUM(DAY(AR2)) -> Wk-4 | AS1: ="Wk-"&WEEKNUM(DAY(AS2)) -> Wk-4 | AT1: ="Wk-"&WEEKNUM(DAY(AT2)) -> Wk-4 | AU1: ="Wk-"&WEEKNUM(DAY(AU2)) -> Wk-4 | AV1: ="Wk-"&WEEKNUM(DAY(AV2)) -> Wk-4 | AW1: ="Wk-"&WEEKNUM(DAY(AW2)) -> Wk-4 | BC1: ="Wk-"&WEEKNUM(DAY(BC2)) -> Wk-5 | BD1: ="Wk-"&WEEKNUM(DAY(BD2)) -> Wk-5 | BE1: ="Wk-"&WEEKNUM(DAY(BE2)) -> Wk-1
B2: Agent id | C2: Agent Name | D2: TL Name | E2: Gender | F2: Campaign | G2: 46266 | H2: =G2+1 -> 46267 | I2: =H2+1 -> 46268 | J2: =I2+1 -> 46269 | K2: =J2+1 -> 46270 | L2: =K2+1 -> 46271 | M2: =L2+1 -> 46272 | N2: Wk -1 | S2: =M2+1 -> 46273 | T2: =S2+1 -> 46274 | U2: =T2+1 -> 46275 | V2: =U2+1 -> 46276 | W2: =V2+1 -> 46277 | X2: =W2+1 -> 46278 | Y2: =X2+1 -> 46279 | Z2: Wk -2 | AE2: =Y2+1 -> 46280 | AF2: =AE2+1 -> 46281 | AG2: =AF2+1 -> 46282 | AH2: =AG2+1 -> 46283 | AI2: =AH2+1 -> 46284 | AJ2: =AI2+1 -> 46285 | AK2: =AJ2+1 -> 46286 | AL2: Wk -3 | AQ2: =AK2+1 -> 46287 | AR2: =AQ2+1 -> 46288 | AS2: =AR2+1 -> 46289 | AT2: =AS2+1 -> 46290 | AU2: =AT2+1 -> 46291 | AV2: =AU2+1 -> 46292 | AW2: =AV2+1 -> 46293 | AX2: Wk -4 | BC2: =AW2+1 -> 46294 | BD2: =BC2+1 -> 46295 | BE2: =BD2+1 -> 46296 | BF2: Wk -5
G3: =UPPER(TEXT(G2,"ddd")) -> TUE | H3: =UPPER(TEXT(H2,"ddd")) -> WED | I3: =UPPER(TEXT(I2,"ddd")) -> THU | J3: =UPPER(TEXT(J2,"ddd")) -> FRI | K3: =UPPER(TEXT(K2,"ddd")) -> SAT | L3: =UPPER(TEXT(L2,"ddd")) -> SUN | M3: =UPPER(TEXT(M2,"ddd")) -> MON | N3: Agent Choice WO | O3: TL Choice WO | P3: CL | Q3: HD | R3: LP | S3: =UPPER(TEXT(S2,"ddd")) -> TUE | T3: =UPPER(TEXT(T2,"ddd")) -> WED | U3: =UPPER(TEXT(U2,"ddd")) -> THU | V3: =UPPER(TEXT(V2,"ddd")) -> FRI | W3: =UPPER(TEXT(W2,"ddd")) -> SAT | X3: =UPPER(TEXT(X2,"ddd")) -> SUN | Y3: =UPPER(TEXT(Y2,"ddd")) -> MON | Z3: Agent Choice WO | AA3: TL Choice WO | AB3: CL | AC3: HD | AD3: LP | AE3: =UPPER(TEXT(AE2,"ddd")) -> TUE | AF3: =UPPER(TEXT(AF2,"ddd")) -> WED | AG3: =UPPER(TEXT(AG2,"ddd")) -> THU | AH3: =UPPER(TEXT(AH2,"ddd")) -> FRI | AI3: =UPPER(TEXT(AI2,"ddd")) -> SAT | AJ3: =UPPER(TEXT(AJ2,"ddd")) -> SUN | AK3: =UPPER(TEXT(AK2,"ddd")) -> MON | AL3: Agent Choice WO | AM3: TL Choice WO | AN3: CL | AO3: HD | AP3: LP | AQ3: =UPPER(TEXT(AQ2,"ddd")) -> TUE | AR3: =UPPER(TEXT(AR2,"ddd")) -> WED | AS3: =UPPER(TEXT(AS2,"ddd")) -> THU | AT3: =UPPER(TEXT(AT2,"ddd")) -> FRI | AU3: =UPPER(TEXT(AU2,"ddd")) -> SAT | AV3: =UPPER(TEXT(AV2,"ddd")) -> SUN | AW3: =UPPER(TEXT(AW2,"ddd")) -> MON | AX3: Agent Choice WO | AY3: TL Choice WO | AZ3: CL | BA3: HD | BB3: LP | BC3: =UPPER(TEXT(BC2,"ddd")) -> TUE | BD3: =UPPER(TEXT(BD2,"ddd")) -> WED | BE3: =UPPER(TEXT(BE2,"ddd")) -> THU | BF3: Agent Choice WO | BG3: TL Choice WO | BH3: CL | BI3: HD | BJ3: LP
A4: 1 | B4: =Morning_Shift!$B4 -> Dritm65 | C4: =IF(IFERROR(VLOOKUP(B4,Morning_Shift!B:C,2,0),"")="",IFERROR(VLOOKUP(B4,Evening_Shift!B:C,2,0),""),IFERROR(VLOOKUP(B4,Morning_Shift!B:C,2,0),"")) -> Aarti | D4: =IF(IFERROR(VLOOKUP(B4,Morning_Shift!B:D,3,0),"")="",IFERROR(VLOOKUP(B4,Evening_Shift!B:D,3,0),""),IFERROR(VLOOKUP(B4,Morning_Shift!B:D,3,0),"")) -> Naina | E4: =IF(IFERROR(VLOOKUP(B4,Morning_Shift!B:E,4,0),"")="",IFERROR(VLOOKUP(B4,Evening_Shift!B:E,4,0),""),IFERROR(VLOOKUP(B4,Morning_Shift!B:E,4,0),"")) -> F | F4: =IF(IFERROR(VLOOKUP(B4,Morning_Shift!B:F,5,0),"")="",IFERROR(VLOOKUP(B4,Evening_Shift!B:F,5,0),""),IFERROR(VLOOKUP(B4,Morning_Shift!B:F,5,0),"")) -> Inbound | G4: =IF(IFERROR(VLOOKUP($B4,Morning_Shift!$B$4:$BJ$61,MATCH(Both_Shift_Roster!G$2,Morning_Shift!$B$2:$BJ$2,0),0),"")="",IFERROR(VLOOKUP($B4,Evening_Shift!$B$4:$BJ$62,MATCH(Both_Shift_Roster!G$2,Evening_Shift!$B$2:$BJ$2,0),0),""),IFERROR(VLOOKUP($B4,Morning_Shift!$B$4:$BJ$61,MATCH(Both_Shift_Roster!G$2,Morning_Shift!$B$2:$BJ$2,0),0),"")) -> 7:00-14:30 | H4: =IF(IFERROR(VLOOKUP($B4,Morning_Shift!$B$4:$BJ$61,MATCH(Both_Shift_Roster!H$2,Morning_Shift!$B$2:$BJ$2,0),0),"")="",IFERROR(VLOOKUP($B4,Evening_Shift!$B$4:$BJ$62,MATCH(Both_Shift_Roster!H$2,Evening_Shift!$B$2:$BJ$2,0),0),""),IFERROR(VLOOKUP($B4,Morning_Shift!$B$4:$BJ$61,MATCH(Both_Shift_Roster!H$2,Morning_Shift!$B$2:$BJ$2,0),0),"")) -> 7:00-14:30 | I4: =IF(IFERROR(VLOOKUP($B4,Morning_Shift!$B$4:$BJ$61,MATCH(Both_Shift_Roster!I$2,Morning_Shift!$B$2:$BJ$2,0),0),"")="",IFERROR(VLOOKUP($B4,Evening_Shift!$B$4:$BJ$62,MATCH(Both_Shift_Roster!I$2,Evening_Shift!$B$2:$BJ$2,0),0),""),IFERROR(VLOOKUP($B4,Morning_Shift!$B$4:$BJ$61,MATCH(Both_Shift_Roster!I$2,Morning_Shift!$B$2:$BJ$2,0),0),"")) -> 7:00-14:30 | J4: =IF(IFERROR(VLOOKUP($B4,Morning_Shift!$B$4:$BJ$61,MATCH(Both_Shift_Roster!J$2,Morning_Shift!$B$2:$BJ$2,0),0),"")="",IFERROR(VLOOKUP($B4,Evening_Shift!$B$4:$BJ$62,MATCH(Both_Shift_Roster!J$2,Evening_Shift!$B$2:$BJ$2,0),0),""),IFERROR(VLOOKUP($B4,Morning_Shift!$B$4:$BJ$61,MATCH(Both_Shift_Roster!J$2,Morning_Shift!$B$2:$BJ$2,0),0),"")) -> 7:00-14:30 | K4: =IF(IFERROR(VLOOKUP($B4,Morning_Shift!$B$4:$BJ$61,MATCH(Both_Shift_Roster!K$2,Morning_Shift!$B$2:$BJ$2,0),0),"")="",IFERROR(VLOOKUP($B4,Evening_Shift!$B$4:$BJ$62,MATCH(Both_Shift_Roster!K$2,Evening_Shift!$B$2:$BJ$2,0),0),""),IFERROR(VLOOKUP($B4,Morning_Shift!$B$4:$BJ$61,MATCH(Both_Shift_Roster!K$2,Morning_Shift!$B$2:$BJ$2,0),0),"")) -> 7:00-14:30 | L4: =IF(IFERROR(VLOOKUP($B4,Morning_Shift!$B$4:$BJ$61,MATCH(Both_Shift_Roster!L$2,Morning_Shift!$B$2:$BJ$2,0),0),"")="",IFERROR(VLOOKUP($B4,Evening_Shift!$B$4:$BJ$62,MATCH(Both_Shift_Roster!L$2,Evening_Shift!$B$2:$BJ$2,0),0),""),IFERROR(VLOOKUP($B4,Morning_Shift!$B$4:$BJ$61,MATCH(Both_Shift_Roster!L$2,Morning_Shift!$B$2:$BJ$2,0),0),"")) -> 7:00-14:30 | M4: =IF(IFERROR(VLOOKUP($B4,Morning_Shift!$B$4:$BJ$61,MATCH(Both_Shift_Roster!M$2,Morning_Shift!$B$2:$BJ$2,0),0),"")="",IFERROR(VLOOKUP($B4,Evening_Shift!$B$4:$BJ$62,MATCH(Both_Shift_Roster!M$2,Evening_Shift!$B$2:$BJ$2,0),0),""),IFERROR(VLOOKUP($B4,Morning_Shift!$B$4:$BJ$61,MATCH(Both_Shift_Roster!M$2,Morning_Shift!$B$2:$BJ$2,0),0),"")) -> 7:00-14:30 | N4: =COUNTIF($G4:$M4,"Agent Choice WO") -> 0 | O4: =COUNTIF($G4:$M4,"TL Choice WO") -> 0 | P4: =COUNTIF($G4:$M4,"CL") -> 0 | Q4: =COUNTIF($G4:$M4,"HD") -> 0 | R4: =COUNTIF($G4:$M4,"LP") -> 0 | S4: =IF(IFERROR(VLOOKUP($B4,Morning_Shift!$B$4:$BJ$61,MATCH(Both_Shift_Roster!S$2,Morning_Shift!$B$2:$BJ$2,0),0),"")="",IFERROR(VLOOKUP($B4,Evening_Shift!$B$4:$BJ$62,MATCH(Both_Shift_Roster!S$2,Evening_Shift!$B$2:$BJ$2,0),0),""),IFERROR(VLOOKUP($B4,Morning_Shift!$B$4:$BJ$61,MATCH(Both_Shift_Roster!S$2,Morning_Shift!$B$2:$BJ$2,0),0),"")) -> 7:00-14:30 | T4: =IF(IFERROR(VLOOKUP($B4,Morning_Shift!$B$4:$BJ$61,MATCH(Both_Shift_Roster!T$2,Morning_Shift!$B$2:$BJ$2,0),0),"")="",IFERROR(VLOOKUP($B4,Evening_Shift!$B$4:$BJ$62,MATCH(Both_Shift_Roster!T$2,Evening_Shift!$B$2:$BJ$2,0),0),""),IFERROR(VLOOKUP($B4,Morning_Shift!$B$4:$BJ$61,MATCH(Both_Shift_Roster!T$2,Morning_Shift!$B$2:$BJ$2,0),0),"")) -> 7:00-14:30 | U4: =IF(IFERROR(VLOOKUP($B4,Morning_Shift!$B$4:$BJ$61,MATCH(Both_Shift_Roster!U$2,Morning_Shift!$B$2:$BJ$2,0),0),"")="",IFERROR(VLOOKUP($B4,Evening_Shift!$B$4:$BJ$62,MATCH(Both_Shift_Roster!U$2,Evening_Shift!$B$2:$BJ$2,0),0),""),IFERROR(VLOOKUP($B4,Morning_Shift!$B$4:$BJ$61,MATCH(Both_Shift_Roster!U$2,Morning_Shift!$B$2:$BJ$2,0),0),"")) -> Agent Choice WO | V4: =IF(IFERROR(VLOOKUP($B4,Morning_Shift!$B$4:$BJ$61,MATCH(Both_Shift_Roster!V$2,Morning_Shift!$B$2:$BJ$2,0),0),"")="",IFERROR(VLOOKUP($B4,Evening_Shift!$B$4:$BJ$62,MATCH(Both_Shift_Roster!V$2,Evening_Shift!$B$2:$BJ$2,0),0),""),IFERROR(VLOOKUP($B4,Morning_Shift!$B$4:$BJ$61,MATCH(Both_Shift_Roster!V$2,Morning_Shift!$B$2:$BJ$2,0),0),"")) -> 7:00-14:30 | W4: =IF(IFERROR(VLOOKUP($B4,Morning_Shift!$B$4:$BJ$61,MATCH(Both_Shift_Roster!W$2,Morning_Shift!$B$2:$BJ$2,0),0),"")="",IFERROR(VLOOKUP($B4,Evening_Shift!$B$4:$BJ$62,MATCH(Both_Shift_Roster!W$2,Evening_Shift!$B$2:$BJ$2,0),0),""),IFERROR(VLOOKUP($B4,Morning_Shift!$B$4:$BJ$61,MATCH(Both_Shift_Roster!W$2,Morning_Shift!$B$2:$BJ$2,0),0),"")) -> 7:00-14:30 | X4: =IF(IFERROR(VLOOKUP($B4,Morning_Shift!$B$4:$BJ$61,MATCH(Both_Shift_Roster!X$2,Morning_Shift!$B$2:$BJ$2,0),0),"")="",IFERROR(VLOOKUP($B4,Evening_Shift!$B$4:$BJ$62,MATCH(Both_Shift_Roster!X$2,Evening_Shift!$B$2:$BJ$2,0),0),""),IFERROR(VLOOKUP($B4,Morning_Shift!$B$4:$BJ$61,MATCH(Both_Shift_Roster!X$2,Morning_Shift!$B$2:$BJ$2,0),0),"")) -> 7:00-14:30 | Y4: =IF(IFERROR(VLOOKUP($B4,Morning_Shift!$B$4:$BJ$61,MATCH(Both_Shift_Roster!Y$2,Morning_Shift!$B$2:$BJ$2,0),0),"")="",IFERROR(VLOOKUP($B4,Evening_Shift!$B$4:$BJ$62,MATCH(Both_Shift_Roster!Y$2,Evening_Shift!$B$2:$BJ$2,0),0),""),IFERROR(VLOOKUP($B4,Morning_Shift!$B$4:$BJ$61,MATCH(Both_Shift_Roster!Y$2,Morning_Shift!$B$2:$BJ$2,0),0),"")) -> 7:00-14:30 | Z4: =COUNTIF($S4:$Y4,"Agent Choice WO") -> 1 | AA4: =COUNTIF($S4:$Y4,"TL Choice WO") -> 0 | AB4: =COUNTIF($S4:$Y4,"CL") -> 0 | AC4: =COUNTIF($S4:$Y4,"HD") -> 0 | AD4: =COUNTIF($S4:$Y4,"LP") -> 0 | AE4: =IF(IFERROR(VLOOKUP($B4,Morning_Shift!$B$4:$BJ$61,MATCH(Both_Shift_Roster!AE$2,Morning_Shift!$B$2:$BJ$2,0),0),"")="",IFERROR(VLOOKUP($B4,Evening_Shift!$B$4:$BJ$62,MATCH(Both_Shift_Roster!AE$2,Evening_Shift!$B$2:$BJ$2,0),0),""),IFERROR(VLOOKUP($B4,Morning_Shift!$B$4:$BJ$61,MATCH(Both_Shift_Roster!AE$2,Morning_Shift!$B$2:$BJ$2,0),0),"")) -> Agent Choice WO | AF4: =IF(IFERROR(VLOOKUP($B4,Morning_Shift!$B$4:$BJ$61,MATCH(Both_Shift_Roster!AF$2,Morning_Shift!$B$2:$BJ$2,0),0),"")="",IFERROR(VLOOKUP($B4,Evening_Shift!$B$4:$BJ$62,MATCH(Both_Shift_Roster!AF$2,Evening_Shift!$B$2:$BJ$2,0),0),""),IFERROR(VLOOKUP($B4,Morning_Shift!$B$4:$BJ$61,MATCH(Both_Shift_Roster!AF$2,Morning_Shift!$B$2:$BJ$2,0),0),"")) -> 7:00-14:30 | AG4: =IF(IFERROR(VLOOKUP($B4,Morning_Shift!$B$4:$BJ$61,MATCH(Both_Shift_Roster!AG$2,Morning_Shift!$B$2:$BJ$2,0),0),"")="",IFERROR(VLOOKUP($B4,Evening_Shift!$B$4:$BJ$62,MATCH(Both_Shift_Roster!AG$2,Evening_Shift!$B$2:$BJ$2,0),0),""),IFERROR(VLOOKUP($B4,Morning_Shift!$B$4:$BJ$61,MATCH(Both_Shift_Roster!AG$2,Morning_Shift!$B$2:$BJ$2,0),0),"")) -> 7:00-14:30 | AH4: =IF(IFERROR(VLOOKUP($B4,Morning_Shift!$B$4:$BJ$61,MATCH(Both_Shift_Roster!AH$2,Morning_Shift!$B$2:$BJ$2,0),0),"")="",IFERROR(VLOOKUP($B4,Evening_Shift!$B$4:$BJ$62,MATCH(Both_Shift_Roster!AH$2,Evening_Shift!$B$2:$BJ$2,0),0),""),IFERROR(VLOOKUP($B4,Morning_Shift!$B$4:$BJ$61,MATCH(Both_Shift_Roster!AH$2,Morning_Shift!$B$2:$BJ$2,0),0),"")) -> 7:00-14:30 | AI4: =IF(IFERROR(VLOOKUP($B4,Morning_Shift!$B$4:$BJ$61,MATCH(Both_Shift_Roster!AI$2,Morning_Shift!$B$2:$BJ$2,0),0),"")="",IFERROR(VLOOKUP($B4,Evening_Shift!$B$4:$BJ$62,MATCH(Both_Shift_Roster!AI$2,Evening_Shift!$B$2:$BJ$2,0),0),""),IFERROR(VLOOKUP($B4,Morning_Shift!$B$4:$BJ$61,MATCH(Both_Shift_Roster!AI$2,Morning_Shift!$B$2:$BJ$2,0),0),"")) -> 7:00-14:30 | AJ4: =IF(IFERROR(VLOOKUP($B4,Morning_Shift!$B$4:$BJ$61,MATCH(Both_Shift_Roster!AJ$2,Morning_Shift!$B$2:$BJ$2,0),0),"")="",IFERROR(VLOOKUP($B4,Evening_Shift!$B$4:$BJ$62,MATCH(Both_Shift_Roster!AJ$2,Evening_Shift!$B$2:$BJ$2,0),0),""),IFERROR(VLOOKUP($B4,Morning_Shift!$B$4:$BJ$61,MATCH(Both_Shift_Roster!AJ$2,Morning_Shift!$B$2:$BJ$2,0),0),"")) -> 7:00-14:30 | AK4: =IF(IFERROR(VLOOKUP($B4,Morning_Shift!$B$4:$BJ$61,MATCH(Both_Shift_Roster!AK$2,Morning_Shift!$B$2:$BJ$2,0),0),"")="",IFERROR(VLOOKUP($B4,Evening_Shift!$B$4:$BJ$62,MATCH(Both_Shift_Roster!AK$2,Evening_Shift!$B$2:$BJ$2,0),0),""),IFERROR(VLOOKUP($B4,Morning_Shift!$B$4:$BJ$61,MATCH(Both_Shift_Roster!AK$2,Morning_Shift!$B$2:$BJ$2,0),0),"")) -> 7:00-14:30 | AL4: =COUNTIF($AE4:$AK4,"Agent Choice WO") -> 1 | AM4: =COUNTIF($AE4:$AK4,"TL Choice WO") -> 0 | AN4: =COUNTIF($AE4:$AK4,"CL") -> 0 | AO4: =COUNTIF($AE4:$AK4,"HD") -> 0 | AP4: =COUNTIF($AE4:$AK4,"LP") -> 0 | AQ4: =IF(IFERROR(VLOOKUP($B4,Morning_Shift!$B$4:$BJ$61,MATCH(Both_Shift_Roster!AQ$2,Morning_Shift!$B$2:$BJ$2,0),0),"")="",IFERROR(VLOOKUP($B4,Evening_Shift!$B$4:$BJ$62,MATCH(Both_Shift_Roster!AQ$2,Evening_Shift!$B$2:$BJ$2,0),0),""),IFERROR(VLOOKUP($B4,Morning_Shift!$B$4:$BJ$61,MATCH(Both_Shift_Roster!AQ$2,Morning_Shift!$B$2:$BJ$2,0),0),"")) -> 7:00-14:30 | AR4: =IF(IFERROR(VLOOKUP($B4,Morning_Shift!$B$4:$BJ$61,MATCH(Both_Shift_Roster!AR$2,Morning_Shift!$B$2:$BJ$2,0),0),"")="",IFERROR(VLOOKUP($B4,Evening_Shift!$B$4:$BJ$62,MATCH(Both_Shift_Roster!AR$2,Evening_Shift!$B$2:$BJ$2,0),0),""),IFERROR(VLOOKUP($B4,Morning_Shift!$B$4:$BJ$61,MATCH(Both_Shift_Roster!AR$2,Morning_Shift!$B$2:$BJ$2,0),0),"")) -> 7:00-14:30 | AS4: =IF(IFERROR(VLOOKUP($B4,Morning_Shift!$B$4:$BJ$61,MATCH(Both_Shift_Roster!AS$2,Morning_Shift!$B$2:$BJ$2,0),0),"")="",IFERROR(VLOOKUP($B4,Evening_Shift!$B$4:$BJ$62,MATCH(Both_Shift_Roster!AS$2,Evening_Shift!$B$2:$BJ$2,0),0),""),IFERROR(VLOOKUP($B4,Morning_Shift!$B$4:$BJ$61,MATCH(Both_Shift_Roster!AS$2,Morning_Shift!$B$2:$BJ$2,0),0),"")) -> Agent Choice WO | AT4: =IF(IFERROR(VLOOKUP($B4,Morning_Shift!$B$4:$BJ$61,MATCH(Both_Shift_Roster!AT$2,Morning_Shift!$B$2:$BJ$2,0),0),"")="",IFERROR(VLOOKUP($B4,Evening_Shift!$B$4:$BJ$62,MATCH(Both_Shift_Roster!AT$2,Evening_Shift!$B$2:$BJ$2,0),0),""),IFERROR(VLOOKUP($B4,Morning_Shift!$B$4:$BJ$61,MATCH(Both_Shift_Roster!AT$2,Morning_Shift!$B$2:$BJ$2,0),0),"")) -> Agent Choice WO | AU4: =IF(IFERROR(VLOOKUP($B4,Morning_Shift!$B$4:$BJ$61,MATCH(Both_Shift_Roster!AU$2,Morning_Shift!$B$2:$BJ$2,0),0),"")="",IFERROR(VLOOKUP($B4,Evening_Shift!$B$4:$BJ$62,MATCH(Both_Shift_Roster!AU$2,Evening_Shift!$B$2:$BJ$2,0),0),""),IFERROR(VLOOKUP($B4,Morning_Shift!$B$4:$BJ$61,MATCH(Both_Shift_Roster!AU$2,Morning_Shift!$B$2:$BJ$2,0),0),"")) -> 7:00-14:30 | AV4: =IF(IFERROR(VLOOKUP($B4,Morning_Shift!$B$4:$BJ$61,MATCH(Both_Shift_Roster!AV$2,Morning_Shift!$B$2:$BJ$2,0),0),"")="",IFERROR(VLOOKUP($B4,Evening_Shift!$B$4:$BJ$62,MATCH(Both_Shift_Roster!AV$2,Evening_Shift!$B$2:$BJ$2,0),0),""),IFERROR(VLOOKUP($B4,Morning_Shift!$B$4:$BJ$61,MATCH(Both_Shift_Roster!AV$2,Morning_Shift!$B$2:$BJ$2,0),0),"")) -> 7:00-14:30 | AW4: =IF(IFERROR(VLOOKUP($B4,Morning_Shift!$B$4:$BJ$61,MATCH(Both_Shift_Roster!AW$2,Morning_Shift!$B$2:$BJ$2,0),0),"")="",IFERROR(VLOOKUP($B4,Evening_Shift!$B$4:$BJ$62,MATCH(Both_Shift_Roster!AW$2,Evening_Shift!$B$2:$BJ$2,0),0),""),IFERROR(VLOOKUP($B4,Morning_Shift!$B$4:$BJ$61,MATCH(Both_Shift_Roster!AW$2,Morning_Shift!$B$2:$BJ$2,0),0),"")) -> 7:00-14:30 | AX4: =COUNTIF($AQ4:$AW4,"Agent Choice WO") -> 2 | AY4: =COUNTIF($AQ4:$AW4,"TL Choice WO") -> 0 | AZ4: =COUNTIF($AQ4:$AW4,"CL") -> 0 | BA4: =COUNTIF($AQ4:$AW4,"HD") -> 0 | BB4: =COUNTIF($AQ4:$AW4,"LP") -> 0 | BC4: =IF(IFERROR(VLOOKUP($B4,Morning_Shift!$B$4:$BJ$61,MATCH(Both_Shift_Roster!BC$2,Morning_Shift!$B$2:$BJ$2,0),0),"")="",IFERROR(VLOOKUP($B4,Evening_Shift!$B$4:$BJ$62,MATCH(Both_Shift_Roster!BC$2,Evening_Shift!$B$2:$BJ$2,0),0),""),IFERROR(VLOOKUP($B4,Morning_Shift!$B$4:$BJ$61,MATCH(Both_Shift_Roster!BC$2,Morning_Shift!$B$2:$BJ$2,0),0),"")) -> 7:00-14:30 | BD4: =IF(IFERROR(VLOOKUP($B4,Morning_Shift!$B$4:$BJ$61,MATCH(Both_Shift_Roster!BD$2,Morning_Shift!$B$2:$BJ$2,0),0),"")="",IFERROR(VLOOKUP($B4,Evening_Shift!$B$4:$BJ$62,MATCH(Both_Shift_Roster!BD$2,Evening_Shift!$B$2:$BJ$2,0),0),""),IFERROR(VLOOKUP($B4,Morning_Shift!$B$4:$BJ$61,MATCH(Both_Shift_Roster!BD$2,Morning_Shift!$B$2:$BJ$2,0),0),"")) -> CL | BE4: =IF(IFERROR(VLOOKUP($B4,Morning_Shift!$B$4:$BJ$61,MATCH(Both_Shift_Roster!BE$2,Morning_Shift!$B$2:$BJ$2,0),0),"")="",IFERROR(VLOOKUP($B4,Evening_Shift!$B$4:$BJ$59,MATCH(Both_Shift_Roster!BE$2,Evening_Shift!$B$2:$BJ$2,0),0),""),IFERROR(VLOOKUP($B4,Morning_Shift!$B$4:$BJ$61,MATCH(Both_Shift_Roster!BE$2,Morning_Shift!$B$2:$BJ$2,0),0),"")) -> 7:00-14:30 | BF4: =COUNTIF($BC4:$BE4,"Agent Choice WO") -> 0 | BG4: =COUNTIF($BC4:$BE4,"TL Choice WO") -> 0 | BH4: =COUNTIF($BC4:$BE4,"CL") -> 1 | BI4: =COUNTIF($BC4:$BE4,"HD") -> 0 | BJ4: =COUNTIF($BC4:$BE4,"LP") -> 0
A5: =A4+1 -> 2 | B5: =Morning_Shift!$B5 -> Dritm140 | C5: =IF(IFERROR(VLOOKUP(B5,Morning_Shift!B:C,2,0),"")="",IFERROR(VLOOKUP(B5,Evening_Shift!B:C,2,0),""),IFERROR(VLOOKUP(B5,Morning_Shift!B:C,2,0),"")) -> Anjana | D5: =IF(IFERROR(VLOOKUP(B5,Morning_Shift!B:D,3,0),"")="",IFERROR(VLOOKUP(B5,Evening_Shift!B:D,3,0),""),IFERROR(VLOOKUP(B5,Morning_Shift!B:D,3,0),"")) -> Naina | E5: =IF(IFERROR(VLOOKUP(B5,Morning_Shift!B:E,4,0),"")="",IFERROR(VLOOKUP(B5,Evening_Shift!B:E,4,0),""),IFERROR(VLOOKUP(B5,Morning_Shift!B:E,4,0),"")) -> F | F5: =IF(IFERROR(VLOOKUP(B5,Morning_Shift!B:F,5,0),"")="",IFERROR(VLOOKUP(B5,Evening_Shift!B:F,5,0),""),IFERROR(VLOOKUP(B5,Morning_Shift!B:F,5,0),"")) -> Inbound | G5: =IF(IFERROR(VLOOKUP($B5,Morning_Shift!$B$4:$BJ$61,MATCH(Both_Shift_Roster!G$2,Morning_Shift!$B$2:$BJ$2,0),0),"")="",IFERROR(VLOOKUP($B5,Evening_Shift!$B$4:$BJ$62,MATCH(Both_Shift_Roster!G$2,Evening_Shift!$B$2:$BJ$2,0),0),""),IFERROR(VLOOKUP($B5,Morning_Shift!$B$4:$BJ$61,MATCH(Both_Shift_Roster!G$2,Morning_Shift!$B$2:$BJ$2,0),0),"")) -> 7:00-14:30 | H5: =IF(IFERROR(VLOOKUP($B5,Morning_Shift!$B$4:$BJ$61,MATCH(Both_Shift_Roster!H$2,Morning_Shift!$B$2:$BJ$2,0),0),"")="",IFERROR(VLOOKUP($B5,Evening_Shift!$B$4:$BJ$62,MATCH(Both_Shift_Roster!H$2,Evening_Shift!$B$2:$BJ$2,0),0),""),IFERROR(VLOOKUP($B5,Morning_Shift!$B$4:$BJ$61,MATCH(Both_Shift_Roster!H$2,Morning_Shift!$B$2:$BJ$2,0),0),"")) -> 7:00-14:30 | I5: =IF(IFERROR(VLOOKUP($B5,Morning_Shift!$B$4:$BJ$61,MATCH(Both_Shift_Roster!I$2,Morning_Shift!$B$2:$BJ$2,0),0),"")="",IFERROR(VLOOKUP($B5,Evening_Shift!$B$4:$BJ$62,MATCH(Both_Shift_Roster!I$2,Evening_Shift!$B$2:$BJ$2,0),0),""),IFERROR(VLOOKUP($B5,Morning_Shift!$B$4:$BJ$61,MATCH(Both_Shift_Roster!I$2,Morning_Shift!$B$2:$BJ$2,0),0),"")) -> Agent Choice WO | J5: =IF(IFERROR(VLOOKUP($B5,Morning_Shift!$B$4:$BJ$61,MATCH(Both_Shift_Roster!J$2,Morning_Shift!$B$2:$BJ$2,0),0),"")="",IFERROR(VLOOKUP($B5,Evening_Shift!$B$4:$BJ$62,MATCH(Both_Shift_Roster!J$2,Evening_Shift!$B$2:$BJ$2,0),0),""),IFERROR(VLOOKUP($B5,Morning_Shift!$B$4:$BJ$61,MATCH(Both_Shift_Roster!J$2,Morning_Shift!$B$2:$BJ$2,0),0),"")) -> 7:00-14:30 | K5: =IF(IFERROR(VLOOKUP($B5,Morning_Shift!$B$4:$BJ$61,MATCH(Both_Shift_Roster!K$2,Morning_Shift!$B$2:$BJ$2,0),0),"")="",IFERROR(VLOOKUP($B5,Evening_Shift!$B$4:$BJ$62,MATCH(Both_Shift_Roster!K$2,Evening_Shift!$B$2:$BJ$2,0),0),""),IFERROR(VLOOKUP($B5,Morning_Shift!$B$4:$BJ$61,MATCH(Both_Shift_Roster!K$2,Morning_Shift!$B$2:$BJ$2,0),0),"")) -> 7:00-14:30 | L5: =IF(IFERROR(VLOOKUP($B5,Morning_Shift!$B$4:$BJ$61,MATCH(Both_Shift_Roster!L$2,Morning_Shift!$B$2:$BJ$2,0),0),"")="",IFERROR(VLOOKUP($B5,Evening_Shift!$B$4:$BJ$62,MATCH(Both_Shift_Roster!L$2,Evening_Shift!$B$2:$BJ$2,0),0),""),IFERROR(VLOOKUP($B5,Morning_Shift!$B$4:$BJ$61,MATCH(Both_Shift_Roster!L$2,Morning_Shift!$B$2:$BJ$2,0),0),"")) -> 7:00-14:30 | M5: =IF(IFERROR(VLOOKUP($B5,Morning_Shift!$B$4:$BJ$61,MATCH(Both_Shift_Roster!M$2,Morning_Shift!$B$2:$BJ$2,0),0),"")="",IFERROR(VLOOKUP($B5,Evening_Shift!$B$4:$BJ$62,MATCH(Both_Shift_Roster!M$2,Evening_Shift!$B$2:$BJ$2,0),0),""),IFERROR(VLOOKUP($B5,Morning_Shift!$B$4:$BJ$61,MATCH(Both_Shift_Roster!M$2,Morning_Shift!$B$2:$BJ$2,0),0),"")) -> 7:00-14:30 | N5: =COUNTIF($G5:$M5,"Agent Choice WO") -> 1 | O5: =COUNTIF($G5:$M5,"TL Choice WO") -> 0 | P5: =COUNTIF($G5:$M5,"CL") -> 0 | Q5: =COUNTIF($G5:$M5,"HD") -> 0 | R5: =COUNTIF($G5:$M5,"LP") -> 0 | S5: =IF(IFERROR(VLOOKUP($B5,Morning_Shift!$B$4:$BJ$61,MATCH(Both_Shift_Roster!S$2,Morning_Shift!$B$2:$BJ$2,0),0),"")="",IFERROR(VLOOKUP($B5,Evening_Shift!$B$4:$BJ$62,MATCH(Both_Shift_Roster!S$2,Evening_Shift!$B$2:$BJ$2,0),0),""),IFERROR(VLOOKUP($B5,Morning_Shift!$B$4:$BJ$61,MATCH(Both_Shift_Roster!S$2,Morning_Shift!$B$2:$BJ$2,0),0),"")) -> 7:00-14:30 | T5: =IF(IFERROR(VLOOKUP($B5,Morning_Shift!$B$4:$BJ$61,MATCH(Both_Shift_Roster!T$2,Morning_Shift!$B$2:$BJ$2,0),0),"")="",IFERROR(VLOOKUP($B5,Evening_Shift!$B$4:$BJ$62,MATCH(Both_Shift_Roster!T$2,Evening_Shift!$B$2:$BJ$2,0),0),""),IFERROR(VLOOKUP($B5,Morning_Shift!$B$4:$BJ$61,MATCH(Both_Shift_Roster!T$2,Morning_Shift!$B$2:$BJ$2,0),0),"")) -> 7:00-14:30 | U5: =IF(IFERROR(VLOOKUP($B5,Morning_Shift!$B$4:$BJ$61,MATCH(Both_Shift_Roster!U$2,Morning_Shift!$B$2:$BJ$2,0),0),"")="",IFERROR(VLOOKUP($B5,Evening_Shift!$B$4:$BJ$62,MATCH(Both_Shift_Roster!U$2,Evening_Shift!$B$2:$BJ$2,0),0),""),IFERROR(VLOOKUP($B5,Morning_Shift!$B$4:$BJ$61,MATCH(Both_Shift_Roster!U$2,Morning_Shift!$B$2:$BJ$2,0),0),"")) -> 7:00-14:30 | V5: =IF(IFERROR(VLOOKUP($B5,Morning_Shift!$B$4:$BJ$61,MATCH(Both_Shift_Roster!V$2,Morning_Shift!$B$2:$BJ$2,0),0),"")="",IFERROR(VLOOKUP($B5,Evening_Shift!$B$4:$BJ$62,MATCH(Both_Shift_Roster!V$2,Evening_Shift!$B$2:$BJ$2,0),0),""),IFERROR(VLOOKUP($B5,Morning_Shift!$B$4:$BJ$61,MATCH(Both_Shift_Roster!V$2,Morning_Shift!$B$2:$BJ$2,0),0),"")) -> 7:00-14:30 | W5: =IF(IFERROR(VLOOKUP($B5,Morning_Shift!$B$4:$BJ$61,MATCH(Both_Shift_Roster!W$2,Morning_Shift!$B$2:$BJ$2,0),0),"")="",IFERROR(VLOOKUP($B5,Evening_Shift!$B$4:$BJ$62,MATCH(Both_Shift_Roster!W$2,Evening_Shift!$B$2:$BJ$2,0),0),""),IFERROR(VLOOKUP($B5,Morning_Shift!$B$4:$BJ$61,MATCH(Both_Shift_Roster!W$2,Morning_Shift!$B$2:$BJ$2,0),0),"")) -> 7:00-14:30 | X5: =IF(IFERROR(VLOOKUP($B5,Morning_Shift!$B$4:$BJ$61,MATCH(Both_Shift_Roster!X$2,Morning_Shift!$B$2:$BJ$2,0),0),"")="",IFERROR(VLOOKUP($B5,Evening_Shift!$B$4:$BJ$62,MATCH(Both_Shift_Roster!X$2,Evening_Shift!$B$2:$BJ$2,0),0),""),IFERROR(VLOOKUP($B5,Morning_Shift!$B$4:$BJ$61,MATCH(Both_Shift_Roster!X$2,Morning_Shift!$B$2:$BJ$2,0),0),"")) -> 7:00-14:30 | Y5: =IF(IFERROR(VLOOKUP($B5,Morning_Shift!$B$4:$BJ$61,MATCH(Both_Shift_Roster!Y$2,Morning_Shift!$B$2:$BJ$2,0),0),"")="",IFERROR(VLOOKUP($B5,Evening_Shift!$B$4:$BJ$62,MATCH(Both_Shift_Roster!Y$2,Evening_Shift!$B$2:$BJ$2,0),0),""),IFERROR(VLOOKUP($B5,Morning_Shift!$B$4:$BJ$61,MATCH(Both_Shift_Roster!Y$2,Morning_Shift!$B$2:$BJ$2,0),0),"")) -> 7:00-14:30 | Z5: =COUNTIF($S5:$Y5,"Agent Choice WO") -> 0 | AA5: =COUNTIF($S5:$Y5,"TL Choice WO") -> 0 | AB5: =COUNTIF($S5:$Y5,"CL") -> 0 | AC5: =COUNTIF($S5:$Y5,"HD") -> 0 | AD5: =COUNTIF($S5:$Y5,"LP") -> 0 | AE5: =IF(IFERROR(VLOOKUP($B5,Morning_Shift!$B$4:$BJ$61,MATCH(Both_Shift_Roster!AE$2,Morning_Shift!$B$2:$BJ$2,0),0),"")="",IFERROR(VLOOKUP($B5,Evening_Shift!$B$4:$BJ$62,MATCH(Both_Shift_Roster!AE$2,Evening_Shift!$B$2:$BJ$2,0),0),""),IFERROR(VLOOKUP($B5,Morning_Shift!$B$4:$BJ$61,MATCH(Both_Shift_Roster!AE$2,Morning_Shift!$B$2:$BJ$2,0),0),"")) -> 7:00-14:30 | AF5: =IF(IFERROR(VLOOKUP($B5,Morning_Shift!$B$4:$BJ$61,MATCH(Both_Shift_Roster!AF$2,Morning_Shift!$B$2:$BJ$2,0),0),"")="",IFERROR(VLOOKUP($B5,Evening_Shift!$B$4:$BJ$62,MATCH(Both_Shift_Roster!AF$2,Evening_Shift!$B$2:$BJ$2,0),0),""),IFERROR(VLOOKUP($B5,Morning_Shift!$B$4:$BJ$61,MATCH(Both_Shift_Roster!AF$2,Morning_Shift!$B$2:$BJ$2,0),0),"")) -> 7:00-14:30 | AG5: =IF(IFERROR(VLOOKUP($B5,Morning_Shift!$B$4:$BJ$61,MATCH(Both_Shift_Roster!AG$2,Morning_Shift!$B$2:$BJ$2,0),0),"")="",IFERROR(VLOOKUP($B5,Evening_Shift!$B$4:$BJ$62,MATCH(Both_Shift_Roster!AG$2,Evening_Shift!$B$2:$BJ$2,0),0),""),IFERROR(VLOOKUP($B5,Morning_Shift!$B$4:$BJ$61,MATCH(Both_Shift_Roster!AG$2,Morning_Shift!$B$2:$BJ$2,0),0),"")) -> 7:00-14:30 | AH5: =IF(IFERROR(VLOOKUP($B5,Morning_Shift!$B$4:$BJ$61,MATCH(Both_Shift_Roster!AH$2,Morning_Shift!$B$2:$BJ$2,0),0),"")="",IFERROR(VLOOKUP($B5,Evening_Shift!$B$4:$BJ$62,MATCH(Both_Shift_Roster!AH$2,Evening_Shift!$B$2:$BJ$2,0),0),""),IFERROR(VLOOKUP($B5,Morning_Shift!$B$4:$BJ$61,MATCH(Both_Shift_Roster!AH$2,Morning_Shift!$B$2:$BJ$2,0),0),"")) -> 7:00-14:30 | AI5: =IF(IFERROR(VLOOKUP($B5,Morning_Shift!$B$4:$BJ$61,MATCH(Both_Shift_Roster!AI$2,Morning_Shift!$B$2:$BJ$2,0),0),"")="",IFERROR(VLOOKUP($B5,Evening_Shift!$B$4:$BJ$62,MATCH(Both_Shift_Roster!AI$2,Evening_Shift!$B$2:$BJ$2,0),0),""),IFERROR(VLOOKUP($B5,Morning_Shift!$B$4:$BJ$61,MATCH(Both_Shift_Roster!AI$2,Morning_Shift!$B$2:$BJ$2,0),0),"")) -> 7:00-14:30 | AJ5: =IF(IFERROR(VLOOKUP($B5,Morning_Shift!$B$4:$BJ$61,MATCH(Both_Shift_Roster!AJ$2,Morning_Shift!$B$2:$BJ$2,0),0),"")="",IFERROR(VLOOKUP($B5,Evening_Shift!$B$4:$BJ$62,MATCH(Both_Shift_Roster!AJ$2,Evening_Shift!$B$2:$BJ$2,0),0),""),IFERROR(VLOOKUP($B5,Morning_Shift!$B$4:$BJ$61,MATCH(Both_Shift_Roster!AJ$2,Morning_Shift!$B$2:$BJ$2,0),0),"")) -> 7:00-14:30 | AK5: =IF(IFERROR(VLOOKUP($B5,Morning_Shift!$B$4:$BJ$61,MATCH(Both_Shift_Roster!AK$2,Morning_Shift!$B$2:$BJ$2,0),0),"")="",IFERROR(VLOOKUP($B5,Evening_Shift!$B$4:$BJ$62,MATCH(Both_Shift_Roster!AK$2,Evening_Shift!$B$2:$BJ$2,0),0),""),IFERROR(VLOOKUP($B5,Morning_Shift!$B$4:$BJ$61,MATCH(Both_Shift_Roster!AK$2,Morning_Shift!$B$2:$BJ$2,0),0),"")) -> 7:00-14:30 | AL5: =COUNTIF($AE5:$AK5,"Agent Choice WO") -> 0 | AM5: =COUNTIF($AE5:$AK5,"TL Choice WO") -> 0 | AN5: =COUNTIF($AE5:$AK5,"CL") -> 0 | AO5: =COUNTIF($AE5:$AK5,"HD") -> 0 | AP5: =COUNTIF($AE5:$AK5,"LP") -> 0 | AQ5: =IF(IFERROR(VLOOKUP($B5,Morning_Shift!$B$4:$BJ$61,MATCH(Both_Shift_Roster!AQ$2,Morning_Shift!$B$2:$BJ$2,0),0),"")="",IFERROR(VLOOKUP($B5,Evening_Shift!$B$4:$BJ$62,MATCH(Both_Shift_Roster!AQ$2,Evening_Shift!$B$2:$BJ$2,0),0),""),IFERROR(VLOOKUP($B5,Morning_Shift!$B$4:$BJ$61,MATCH(Both_Shift_Roster!AQ$2,Morning_Shift!$B$2:$BJ$2,0),0),"")) -> Agent Choice WO | AR5: =IF(IFERROR(VLOOKUP($B5,Morning_Shift!$B$4:$BJ$61,MATCH(Both_Shift_Roster!AR$2,Morning_Shift!$B$2:$BJ$2,0),0),"")="",IFERROR(VLOOKUP($B5,Evening_Shift!$B$4:$BJ$62,MATCH(Both_Shift_Roster!AR$2,Evening_Shift!$B$2:$BJ$2,0),0),""),IFERROR(VLOOKUP($B5,Morning_Shift!$B$4:$BJ$61,MATCH(Both_Shift_Roster!AR$2,Morning_Shift!$B$2:$BJ$2,0),0),"")) -> Agent Choice WO | AS5: =IF(IFERROR(VLOOKUP($B5,Morning_Shift!$B$4:$BJ$61,MATCH(Both_Shift_Roster!AS$2,Morning_Shift!$B$2:$BJ$2,0),0),"")="",IFERROR(VLOOKUP($B5,Evening_Shift!$B$4:$BJ$62,MATCH(Both_Shift_Roster!AS$2,Evening_Shift!$B$2:$BJ$2,0),0),""),IFERROR(VLOOKUP($B5,Morning_Shift!$B$4:$BJ$61,MATCH(Both_Shift_Roster!AS$2,Morning_Shift!$B$2:$BJ$2,0),0),"")) -> Agent Choice WO | AT5: =IF(IFERROR(VLOOKUP($B5,Morning_Shift!$B$4:$BJ$61,MATCH(Both_Shift_Roster!AT$2,Morning_Shift!$B$2:$BJ$2,0),0),"")="",IFERROR(VLOOKUP($B5,Evening_Shift!$B$4:$BJ$62,MATCH(Both_Shift_Roster!AT$2,Evening_Shift!$B$2:$BJ$2,0),0),""),IFERROR(VLOOKUP($B5,Morning_Shift!$B$4:$BJ$61,MATCH(Both_Shift_Roster!AT$2,Morning_Shift!$B$2:$BJ$2,0),0),"")) -> CL | AU5: =IF(IFERROR(VLOOKUP($B5,Morning_Shift!$B$4:$BJ$61,MATCH(Both_Shift_Roster!AU$2,Morning_Shift!$B$2:$BJ$2,0),0),"")="",IFERROR(VLOOKUP($B5,Evening_Shift!$B$4:$BJ$62,MATCH(Both_Shift_Roster!AU$2,Evening_Shift!$B$2:$BJ$2,0),0),""),IFERROR(VLOOKUP($B5,Morning_Shift!$B$4:$BJ$61,MATCH(Both_Shift_Roster!AU$2,Morning_Shift!$B$2:$BJ$2,0),0),"")) -> 7:00-14:30 | AV5: =IF(IFERROR(VLOOKUP($B5,Morning_Shift!$B$4:$BJ$61,MATCH(Both_Shift_Roster!AV$2,Morning_Shift!$B$2:$BJ$2,0),0),"")="",IFERROR(VLOOKUP($B5,Evening_Shift!$B$4:$BJ$62,MATCH(Both_Shift_Roster!AV$2,Evening_Shift!$B$2:$BJ$2,0),0),""),IFERROR(VLOOKUP($B5,Morning_Shift!$B$4:$BJ$61,MATCH(Both_Shift_Roster!AV$2,Morning_Shift!$B$2:$BJ$2,0),0),"")) -> 7:00-14:30 | AW5: =IF(IFERROR(VLOOKUP($B5,Morning_Shift!$B$4:$BJ$61,MATCH(Both_Shift_Roster!AW$2,Morning_Shift!$B$2:$BJ$2,0),0),"")="",IFERROR(VLOOKUP($B5,Evening_Shift!$B$4:$BJ$62,MATCH(Both_Shift_Roster!AW$2,Evening_Shift!$B$2:$BJ$2,0),0),""),IFERROR(VLOOKUP($B5,Morning_Shift!$B$4:$BJ$61,MATCH(Both_Shift_Roster!AW$2,Morning_Shift!$B$2:$BJ$2,0),0),"")) -> 7:00-14:30 | AX5: =COUNTIF($AQ5:$AW5,"Agent Choice WO") -> 3 | AY5: =COUNTIF($AQ5:$AW5,"TL Choice WO") -> 0 | AZ5: =COUNTIF($AQ5:$AW5,"CL") -> 1 | BA5: =COUNTIF($AQ5:$AW5,"HD") -> 0 | BB5: =COUNTIF($AQ5:$AW5,"LP") -> 0 | BC5: =IF(IFERROR(VLOOKUP($B5,Morning_Shift!$B$4:$BJ$61,MATCH(Both_Shift_Roster!BC$2,Morning_Shift!$B$2:$BJ$2,0),0),"")="",IFERROR(VLOOKUP($B5,Evening_Shift!$B$4:$BJ$62,MATCH(Both_Shift_Roster!BC$2,Evening_Shift!$B$2:$BJ$2,0),0),""),IFERROR(VLOOKUP($B5,Morning_Shift!$B$4:$BJ$61,MATCH(Both_Shift_Roster!BC$2,Morning_Shift!$B$2:$BJ$2,0),0),"")) -> 7:00-14:30 | BD5: =IF(IFERROR(VLOOKUP($B5,Morning_Shift!$B$4:$BJ$61,MATCH(Both_Shift_Roster!BD$2,Morning_Shift!$B$2:$BJ$2,0),0),"")="",IFERROR(VLOOKUP($B5,Evening_Shift!$B$4:$BJ$62,MATCH(Both_Shift_Roster!BD$2,Evening_Shift!$B$2:$BJ$2,0),0),""),IFERROR(VLOOKUP($B5,Morning_Shift!$B$4:$BJ$61,MATCH(Both_Shift_Roster!BD$2,Morning_Shift!$B$2:$BJ$2,0),0),"")) -> 7:00-14:30 | BE5: =IF(IFERROR(VLOOKUP($B5,Morning_Shift!$B$4:$BJ$61,MATCH(Both_Shift_Roster!BE$2,Morning_Shift!$B$2:$BJ$2,0),0),"")="",IFERROR(VLOOKUP($B5,Evening_Shift!$B$4:$BJ$59,MATCH(Both_Shift_Roster!BE$2,Evening_Shift!$B$2:$BJ$2,0),0),""),IFERROR(VLOOKUP($B5,Morning_Shift!$B$4:$BJ$61,MATCH(Both_Shift_Roster!BE$2,Morning_Shift!$B$2:$BJ$2,0),0),"")) -> 7:00-14:30 | BF5: =COUNTIF($BC5:$BE5,"Agent Choice WO") -> 0 | BG5: =COUNTIF($BC5:$BE5,"TL Choice WO") -> 0 | BH5: =COUNTIF($BC5:$BE5,"CL") -> 0 | BI5: =COUNTIF($BC5:$BE5,"HD") -> 0 | BJ5: =COUNTIF($BC5:$BE5,"LP") -> 0
A6: =A5+1 -> 3 | B6: =Morning_Shift!$B6 -> Dritm14 | C6: =IF(IFERROR(VLOOKUP(B6,Morning_Shift!B:C,2,0),"")="",IFERROR(VLOOKUP(B6,Evening_Shift!B:C,2,0),""),IFERROR(VLOOKUP(B6,Morning_Shift!B:C,2,0),"")) -> Anjana | D6: =IF(IFERROR(VLOOKUP(B6,Morning_Shift!B:D,3,0),"")="",IFERROR(VLOOKUP(B6,Evening_Shift!B:D,3,0),""),IFERROR(VLOOKUP(B6,Morning_Shift!B:D,3,0),"")) -> Naina | E6: =IF(IFERROR(VLOOKUP(B6,Morning_Shift!B:E,4,0),"")="",IFERROR(VLOOKUP(B6,Evening_Shift!B:E,4,0),""),IFERROR(VLOOKUP(B6,Morning_Shift!B:E,4,0),"")) -> F | F6: =IF(IFERROR(VLOOKUP(B6,Morning_Shift!B:F,5,0),"")="",IFERROR(VLOOKUP(B6,Evening_Shift!B:F,5,0),""),IFERROR(VLOOKUP(B6,Morning_Shift!B:F,5,0),"")) -> Himseva manual Inbound | G6: =IF(IFERROR(VLOOKUP($B6,Morning_Shift!$B$4:$BJ$61,MATCH(Both_Shift_Roster!G$2,Morning_Shift!$B$2:$BJ$2,0),0),"")="",IFERROR(VLOOKUP($B6,Evening_Shift!$B$4:$BJ$62,MATCH(Both_Shift_Roster!G$2,Evening_Shift!$B$2:$BJ$2,0),0),""),IFERROR(VLOOKUP($B6,Morning_Shift!$B$4:$BJ$61,MATCH(Both_Shift_Roster!G$2,Morning_Shift!$B$2:$BJ$2,0),0),"")) -> 10:00-17:30 | H6: =IF(IFERROR(VLOOKUP($B6,Morning_Shift!$B$4:$BJ$61,MATCH(Both_Shift_Roster!H$2,Morning_Shift!$B$2:$BJ$2,0),0),"")="",IFERROR(VLOOKUP($B6,Evening_Shift!$B$4:$BJ$62,MATCH(Both_Shift_Roster!H$2,Evening_Shift!$B$2:$BJ$2,0),0),""),IFERROR(VLOOKUP($B6,Morning_Shift!$B$4:$BJ$61,MATCH(Both_Shift_Roster!H$2,Morning_Shift!$B$2:$BJ$2,0),0),"")) -> 10:00-17:30 | I6: =IF(IFERROR(VLOOKUP($B6,Morning_Shift!$B$4:$BJ$61,MATCH(Both_Shift_Roster!I$2,Morning_Shift!$B$2:$BJ$2,0),0),"")="",IFERROR(VLOOKUP($B6,Evening_Shift!$B$4:$BJ$62,MATCH(Both_Shift_Roster!I$2,Evening_Shift!$B$2:$BJ$2,0),0),""),IFERROR(VLOOKUP($B6,Morning_Shift!$B$4:$BJ$61,MATCH(Both_Shift_Roster!I$2,Morning_Shift!$B$2:$BJ$2,0),0),"")) -> 10:00-17:30 | J6: =IF(IFERROR(VLOOKUP($B6,Morning_Shift!$B$4:$BJ$61,MATCH(Both_Shift_Roster!J$2,Morning_Shift!$B$2:$BJ$2,0),0),"")="",IFERROR(VLOOKUP($B6,Evening_Shift!$B$4:$BJ$62,MATCH(Both_Shift_Roster!J$2,Evening_Shift!$B$2:$BJ$2,0),0),""),IFERROR(VLOOKUP($B6,Morning_Shift!$B$4:$BJ$61,MATCH(Both_Shift_Roster!J$2,Morning_Shift!$B$2:$BJ$2,0),0),"")) -> 10:00-17:30 | K6: =IF(IFERROR(VLOOKUP($B6,Morning_Shift!$B$4:$BJ$61,MATCH(Both_Shift_Roster!K$2,Morning_Shift!$B$2:$BJ$2,0),0),"")="",IFERROR(VLOOKUP($B6,Evening_Shift!$B$4:$BJ$62,MATCH(Both_Shift_Roster!K$2,Evening_Shift!$B$2:$BJ$2,0),0),""),IFERROR(VLOOKUP($B6,Morning_Shift!$B$4:$BJ$61,MATCH(Both_Shift_Roster!K$2,Morning_Shift!$B$2:$BJ$2,0),0),"")) -> 10:00-17:30 | L6: =IF(IFERROR(VLOOKUP($B6,Morning_Shift!$B$4:$BJ$61,MATCH(Both_Shift_Roster!L$2,Morning_Shift!$B$2:$BJ$2,0),0),"")="",IFERROR(VLOOKUP($B6,Evening_Shift!$B$4:$BJ$62,MATCH(Both_Shift_Roster!L$2,Evening_Shift!$B$2:$BJ$2,0),0),""),IFERROR(VLOOKUP($B6,Morning_Shift!$B$4:$BJ$61,MATCH(Both_Shift_Roster!L$2,Morning_Shift!$B$2:$BJ$2,0),0),"")) -> 10:00-17:30 | M6: =IF(IFERROR(VLOOKUP($B6,Morning_Shift!$B$4:$BJ$61,MATCH(Both_Shift_Roster!M$2,Morning_Shift!$B$2:$BJ$2,0),0),"")="",IFERROR(VLOOKUP($B6,Evening_Shift!$B$4:$BJ$62,MATCH(Both_Shift_Roster!M$2,Evening_Shift!$B$2:$BJ$2,0),0),""),IFERROR(VLOOKUP($B6,Morning_Shift!$B$4:$BJ$61,MATCH(Both_Shift_Roster!M$2,Morning_Shift!$B$2:$BJ$2,0),0),"")) -> 10:00-17:30 | N6: =COUNTIF($G6:$M6,"Agent Choice WO") -> 0 | O6: =COUNTIF($G6:$M6,"TL Choice WO") -> 0 | P6: =COUNTIF($G6:$M6,"CL") -> 0 | Q6: =COUNTIF($G6:$M6,"HD") -> 0 | R6: =COUNTIF($G6:$M6,"LP") -> 0 | S6: =IF(IFERROR(VLOOKUP($B6,Morning_Shift!$B$4:$BJ$61,MATCH(Both_Shift_Roster!S$2,Morning_Shift!$B$2:$BJ$2,0),0),"")="",IFERROR(VLOOKUP($B6,Evening_Shift!$B$4:$BJ$62,MATCH(Both_Shift_Roster!S$2,Evening_Shift!$B$2:$BJ$2,0),0),""),IFERROR(VLOOKUP($B6,Morning_Shift!$B$4:$BJ$61,MATCH(Both_Shift_Roster!S$2,Morning_Shift!$B$2:$BJ$2,0),0),"")) -> 10:00-17:30 | T6: =IF(IFERROR(VLOOKUP($B6,Morning_Shift!$B$4:$BJ$61,MATCH(Both_Shift_Roster!T$2,Morning_Shift!$B$2:$BJ$2,0),0),"")="",IFERROR(VLOOKUP($B6,Evening_Shift!$B$4:$BJ$62,MATCH(Both_Shift_Roster!T$2,Evening_Shift!$B$2:$BJ$2,0),0),""),IFERROR(VLOOKUP($B6,Morning_Shift!$B$4:$BJ$61,MATCH(Both_Shift_Roster!T$2,Morning_Shift!$B$2:$BJ$2,0),0),"")) -> Agent Choice WO | U6: =IF(IFERROR(VLOOKUP($B6,Morning_Shift!$B$4:$BJ$61,MATCH(Both_Shift_Roster!U$2,Morning_Shift!$B$2:$BJ$2,0),0),"")="",IFERROR(VLOOKUP($B6,Evening_Shift!$B$4:$BJ$62,MATCH(Both_Shift_Roster!U$2,Evening_Shift!$B$2:$BJ$2,0),0),""),IFERROR(VLOOKUP($B6,Morning_Shift!$B$4:$BJ$61,MATCH(Both_Shift_Roster!U$2,Morning_Shift!$B$2:$BJ$2,0),0),"")) -> 10:00-17:30 | V6: =IF(IFERROR(VLOOKUP($B6,Morning_Shift!$B$4:$BJ$61,MATCH(Both_Shift_Roster!V$2,Morning_Shift!$B$2:$BJ$2,0),0),"")="",IFERROR(VLOOKUP($B6,Evening_Shift!$B$4:$BJ$62,MATCH(Both_Shift_Roster!V$2,Evening_Shift!$B$2:$BJ$2,0),0),""),IFERROR(VLOOKUP($B6,Morning_Shift!$B$4:$BJ$61,MATCH(Both_Shift_Roster!V$2,Morning_Shift!$B$2:$BJ$2,0),0),"")) -> 10:00-17:30 | W6: =IF(IFERROR(VLOOKUP($B6,Morning_Shift!$B$4:$BJ$61,MATCH(Both_Shift_Roster!W$2,Morning_Shift!$B$2:$BJ$2,0),0),"")="",IFERROR(VLOOKUP($B6,Evening_Shift!$B$4:$BJ$62,MATCH(Both_Shift_Roster!W$2,Evening_Shift!$B$2:$BJ$2,0),0),""),IFERROR(VLOOKUP($B6,Morning_Shift!$B$4:$BJ$61,MATCH(Both_Shift_Roster!W$2,Morning_Shift!$B$2:$BJ$2,0),0),"")) -> 10:00-17:30 | X6: =IF(IFERROR(VLOOKUP($B6,Morning_Shift!$B$4:$BJ$61,MATCH(Both_Shift_Roster!X$2,Morning_Shift!$B$2:$BJ$2,0),0),"")="",IFERROR(VLOOKUP($B6,Evening_Shift!$B$4:$BJ$62,MATCH(Both_Shift_Roster!X$2,Evening_Shift!$B$2:$BJ$2,0),0),""),IFERROR(VLOOKUP($B6,Morning_Shift!$B$4:$BJ$61,MATCH(Both_Shift_Roster!X$2,Morning_Shift!$B$2:$BJ$2,0),0),"")) -> Agent Choice WO | Y6: =IF(IFERROR(VLOOKUP($B6,Morning_Shift!$B$4:$BJ$61,MATCH(Both_Shift_Roster!Y$2,Morning_Shift!$B$2:$BJ$2,0),0),"")="",IFERROR(VLOOKUP($B6,Evening_Shift!$B$4:$BJ$62,MATCH(Both_Shift_Roster!Y$2,Evening_Shift!$B$2:$BJ$2,0),0),""),IFERROR(VLOOKUP($B6,Morning_Shift!$B$4:$BJ$61,MATCH(Both_Shift_Roster!Y$2,Morning_Shift!$B$2:$BJ$2,0),0),"")) -> TL Choice WO | Z6: =COUNTIF($S6:$Y6,"Agent Choice WO") -> 2 | AA6: =COUNTIF($S6:$Y6,"TL Choice WO") -> 1 | AB6: =COUNTIF($S6:$Y6,"CL") -> 0 | AC6: =COUNTIF($S6:$Y6,"HD") -> 0 | AD6: =COUNTIF($S6:$Y6,"LP") -> 0 | AE6: =IF(IFERROR(VLOOKUP($B6,Morning_Shift!$B$4:$BJ$61,MATCH(Both_Shift_Roster!AE$2,Morning_Shift!$B$2:$BJ$2,0),0),"")="",IFERROR(VLOOKUP($B6,Evening_Shift!$B$4:$BJ$62,MATCH(Both_Shift_Roster!AE$2,Evening_Shift!$B$2:$BJ$2,0),0),""),IFERROR(VLOOKUP($B6,Morning_Shift!$B$4:$BJ$61,MATCH(Both_Shift_Roster!AE$2,Morning_Shift!$B$2:$BJ$2,0),0),"")) -> 10:00-17:30 | AF6: =IF(IFERROR(VLOOKUP($B6,Morning_Shift!$B$4:$BJ$61,MATCH(Both_Shift_Roster!AF$2,Morning_Shift!$B$2:$BJ$2,0),0),"")="",IFERROR(VLOOKUP($B6,Evening_Shift!$B$4:$BJ$62,MATCH(Both_Shift_Roster!AF$2,Evening_Shift!$B$2:$BJ$2,0),0),""),IFERROR(VLOOKUP($B6,Morning_Shift!$B$4:$BJ$61,MATCH(Both_Shift_Roster!AF$2,Morning_Shift!$B$2:$BJ$2,0),0),"")) -> 10:00-17:30 | AG6: =IF(IFERROR(VLOOKUP($B6,Morning_Shift!$B$4:$BJ$61,MATCH(Both_Shift_Roster!AG$2,Morning_Shift!$B$2:$BJ$2,0),0),"")="",IFERROR(VLOOKUP($B6,Evening_Shift!$B$4:$BJ$62,MATCH(Both_Shift_Roster!AG$2,Evening_Shift!$B$2:$BJ$2,0),0),""),IFERROR(VLOOKUP($B6,Morning_Shift!$B$4:$BJ$61,MATCH(Both_Shift_Roster!AG$2,Morning_Shift!$B$2:$BJ$2,0),0),"")) -> 10:00-17:30 | AH6: =IF(IFERROR(VLOOKUP($B6,Morning_Shift!$B$4:$BJ$61,MATCH(Both_Shift_Roster!AH$2,Morning_Shift!$B$2:$BJ$2,0),0),"")="",IFERROR(VLOOKUP($B6,Evening_Shift!$B$4:$BJ$62,MATCH(Both_Shift_Roster!AH$2,Evening_Shift!$B$2:$BJ$2,0),0),""),IFERROR(VLOOKUP($B6,Morning_Shift!$B$4:$BJ$61,MATCH(Both_Shift_Roster!AH$2,Morning_Shift!$B$2:$BJ$2,0),0),"")) -> 10:00-17:30 | AI6: =IF(IFERROR(VLOOKUP($B6,Morning_Shift!$B$4:$BJ$61,MATCH(Both_Shift_Roster!AI$2,Morning_Shift!$B$2:$BJ$2,0),0),"")="",IFERROR(VLOOKUP($B6,Evening_Shift!$B$4:$BJ$62,MATCH(Both_Shift_Roster!AI$2,Evening_Shift!$B$2:$BJ$2,0),0),""),IFERROR(VLOOKUP($B6,Morning_Shift!$B$4:$BJ$61,MATCH(Both_Shift_Roster!AI$2,Morning_Shift!$B$2:$BJ$2,0),0),"")) -> 10:00-17:30 | AJ6: =IF(IFERROR(VLOOKUP($B6,Morning_Shift!$B$4:$BJ$61,MATCH(Both_Shift_Roster!AJ$2,Morning_Shift!$B$2:$BJ$2,0),0),"")="",IFERROR(VLOOKUP($B6,Evening_Shift!$B$4:$BJ$62,MATCH(Both_Shift_Roster!AJ$2,Evening_Shift!$B$2:$BJ$2,0),0),""),IFERROR(VLOOKUP($B6,Morning_Shift!$B$4:$BJ$61,MATCH(Both_Shift_Roster!AJ$2,Morning_Shift!$B$2:$BJ$2,0),0),"")) -> Agent Choice WO | AK6: =IF(IFERROR(VLOOKUP($B6,Morning_Shift!$B$4:$BJ$61,MATCH(Both_Shift_Roster!AK$2,Morning_Shift!$B$2:$BJ$2,0),0),"")="",IFERROR(VLOOKUP($B6,Evening_Shift!$B$4:$BJ$62,MATCH(Both_Shift_Roster!AK$2,Evening_Shift!$B$2:$BJ$2,0),0),""),IFERROR(VLOOKUP($B6,Morning_Shift!$B$4:$BJ$61,MATCH(Both_Shift_Roster!AK$2,Morning_Shift!$B$2:$BJ$2,0),0),"")) -> 10:00-17:30 | AL6: =COUNTIF($AE6:$AK6,"Agent Choice WO") -> 1 | AM6: =COUNTIF($AE6:$AK6,"TL Choice WO") -> 0 | AN6: =COUNTIF($AE6:$AK6,"CL") -> 0 | AO6: =COUNTIF($AE6:$AK6,"HD") -> 0 | AP6: =COUNTIF($AE6:$AK6,"LP") -> 0 | AQ6: =IF(IFERROR(VLOOKUP($B6,Morning_Shift!$B$4:$BJ$61,MATCH(Both_Shift_Roster!AQ$2,Morning_Shift!$B$2:$BJ$2,0),0),"")="",IFERROR(VLOOKUP($B6,Evening_Shift!$B$4:$BJ$62,MATCH(Both_Shift_Roster!AQ$2,Evening_Shift!$B$2:$BJ$2,0),0),""),IFERROR(VLOOKUP($B6,Morning_Shift!$B$4:$BJ$61,MATCH(Both_Shift_Roster!AQ$2,Morning_Shift!$B$2:$BJ$2,0),0),"")) -> 10:00-17:30 | AR6: =IF(IFERROR(VLOOKUP($B6,Morning_Shift!$B$4:$BJ$61,MATCH(Both_Shift_Roster!AR$2,Morning_Shift!$B$2:$BJ$2,0),0),"")="",IFERROR(VLOOKUP($B6,Evening_Shift!$B$4:$BJ$62,MATCH(Both_Shift_Roster!AR$2,Evening_Shift!$B$2:$BJ$2,0),0),""),IFERROR(VLOOKUP($B6,Morning_Shift!$B$4:$BJ$61,MATCH(Both_Shift_Roster!AR$2,Morning_Shift!$B$2:$BJ$2,0),0),"")) -> 10:00-17:30 | AS6: =IF(IFERROR(VLOOKUP($B6,Morning_Shift!$B$4:$BJ$61,MATCH(Both_Shift_Roster!AS$2,Morning_Shift!$B$2:$BJ$2,0),0),"")="",IFERROR(VLOOKUP($B6,Evening_Shift!$B$4:$BJ$62,MATCH(Both_Shift_Roster!AS$2,Evening_Shift!$B$2:$BJ$2,0),0),""),IFERROR(VLOOKUP($B6,Morning_Shift!$B$4:$BJ$61,MATCH(Both_Shift_Roster!AS$2,Morning_Shift!$B$2:$BJ$2,0),0),"")) -> 10:00-17:30 | AT6: =IF(IFERROR(VLOOKUP($B6,Morning_Shift!$B$4:$BJ$61,MATCH(Both_Shift_Roster!AT$2,Morning_Shift!$B$2:$BJ$2,0),0),"")="",IFERROR(VLOOKUP($B6,Evening_Shift!$B$4:$BJ$62,MATCH(Both_Shift_Roster!AT$2,Evening_Shift!$B$2:$BJ$2,0),0),""),IFERROR(VLOOKUP($B6,Morning_Shift!$B$4:$BJ$61,MATCH(Both_Shift_Roster!AT$2,Morning_Shift!$B$2:$BJ$2,0),0),"")) -> 10:00-17:30 | AU6: =IF(IFERROR(VLOOKUP($B6,Morning_Shift!$B$4:$BJ$61,MATCH(Both_Shift_Roster!AU$2,Morning_Shift!$B$2:$BJ$2,0),0),"")="",IFERROR(VLOOKUP($B6,Evening_Shift!$B$4:$BJ$62,MATCH(Both_Shift_Roster!AU$2,Evening_Shift!$B$2:$BJ$2,0),0),""),IFERROR(VLOOKUP($B6,Morning_Shift!$B$4:$BJ$61,MATCH(Both_Shift_Roster!AU$2,Morning_Shift!$B$2:$BJ$2,0),0),"")) -> 10:00-17:30 | AV6: =IF(IFERROR(VLOOKUP($B6,Morning_Shift!$B$4:$BJ$61,MATCH(Both_Shift_Roster!AV$2,Morning_Shift!$B$2:$BJ$2,0),0),"")="",IFERROR(VLOOKUP($B6,Evening_Shift!$B$4:$BJ$62,MATCH(Both_Shift_Roster!AV$2,Evening_Shift!$B$2:$BJ$2,0),0),""),IFERROR(VLOOKUP($B6,Morning_Shift!$B$4:$BJ$61,MATCH(Both_Shift_Roster!AV$2,Morning_Shift!$B$2:$BJ$2,0),0),"")) -> Agent Choice WO | AW6: =IF(IFERROR(VLOOKUP($B6,Morning_Shift!$B$4:$BJ$61,MATCH(Both_Shift_Roster!AW$2,Morning_Shift!$B$2:$BJ$2,0),0),"")="",IFERROR(VLOOKUP($B6,Evening_Shift!$B$4:$BJ$62,MATCH(Both_Shift_Roster!AW$2,Evening_Shift!$B$2:$BJ$2,0),0),""),IFERROR(VLOOKUP($B6,Morning_Shift!$B$4:$BJ$61,MATCH(Both_Shift_Roster!AW$2,Morning_Shift!$B$2:$BJ$2,0),0),"")) -> 10:00-17:30 | AX6: =COUNTIF($AQ6:$AW6,"Agent Choice WO") -> 1 | AY6: =COUNTIF($AQ6:$AW6,"TL Choice WO") -> 0 | AZ6: =COUNTIF($AQ6:$AW6,"CL") -> 0 | BA6: =COUNTIF($AQ6:$AW6,"HD") -> 0 | BB6: =COUNTIF($AQ6:$AW6,"LP") -> 0 | BC6: =IF(IFERROR(VLOOKUP($B6,Morning_Shift!$B$4:$BJ$61,MATCH(Both_Shift_Roster!BC$2,Morning_Shift!$B$2:$BJ$2,0),0),"")="",IFERROR(VLOOKUP($B6,Evening_Shift!$B$4:$BJ$62,MATCH(Both_Shift_Roster!BC$2,Evening_Shift!$B$2:$BJ$2,0),0),""),IFERROR(VLOOKUP($B6,Morning_Shift!$B$4:$BJ$61,MATCH(Both_Shift_Roster!BC$2,Morning_Shift!$B$2:$BJ$2,0),0),"")) -> 10:00-17:30 | BD6: =IF(IFERROR(VLOOKUP($B6,Morning_Shift!$B$4:$BJ$61,MATCH(Both_Shift_Roster!BD$2,Morning_Shift!$B$2:$BJ$2,0),0),"")="",IFERROR(VLOOKUP($B6,Evening_Shift!$B$4:$BJ$62,MATCH(Both_Shift_Roster!BD$2,Evening_Shift!$B$2:$BJ$2,0),0),""),IFERROR(VLOOKUP($B6,Morning_Shift!$B$4:$BJ$61,MATCH(Both_Shift_Roster!BD$2,Morning_Shift!$B$2:$BJ$2,0),0),"")) -> 10:00-17:30 | BE6: =IF(IFERROR(VLOOKUP($B6,Morning_Shift!$B$4:$BJ$61,MATCH(Both_Shift_Roster!BE$2,Morning_Shift!$B$2:$BJ$2,0),0),"")="",IFERROR(VLOOKUP($B6,Evening_Shift!$B$4:$BJ$59,MATCH(Both_Shift_Roster!BE$2,Evening_Shift!$B$2:$BJ$2,0),0),""),IFERROR(VLOOKUP($B6,Morning_Shift!$B$4:$BJ$61,MATCH(Both_Shift_Roster!BE$2,Morning_Shift!$B$2:$BJ$2,0),0),"")) -> 10:00-17:30 | BF6: =COUNTIF($BC6:$BE6,"Agent Choice WO") -> 0 | BG6: =COUNTIF($BC6:$BE6,"TL Choice WO") -> 0 | BH6: =COUNTIF($BC6:$BE6,"CL") -> 0 | BI6: =COUNTIF($BC6:$BE6,"HD") -> 0 | BJ6: =COUNTIF($BC6:$BE6,"LP") -> 0
A7: =A6+1 -> 4 | B7: =Morning_Shift!$B7 -> Dritm103 | C7: =IF(IFERROR(VLOOKUP(B7,Morning_Shift!B:C,2,0),"")="",IFERROR(VLOOKUP(B7,Evening_Shift!B:C,2,0),""),IFERROR(VLOOKUP(B7,Morning_Shift!B:C,2,0),"")) -> Anjana Thakur | D7: =IF(IFERROR(VLOOKUP(B7,Morning_Shift!B:D,3,0),"")="",IFERROR(VLOOKUP(B7,Evening_Shift!B:D,3,0),""),IFERROR(VLOOKUP(B7,Morning_Shift!B:D,3,0),"")) -> Naina | E7: =IF(IFERROR(VLOOKUP(B7,Morning_Shift!B:E,4,0),"")="",IFERROR(VLOOKUP(B7,Evening_Shift!B:E,4,0),""),IFERROR(VLOOKUP(B7,Morning_Shift!B:E,4,0),"")) -> F | F7: =IF(IFERROR(VLOOKUP(B7,Morning_Shift!B:F,5,0),"")="",IFERROR(VLOOKUP(B7,Evening_Shift!B:F,5,0),""),IFERROR(VLOOKUP(B7,Morning_Shift!B:F,5,0),"")) -> Inbound | G7: =IF(IFERROR(VLOOKUP($B7,Morning_Shift!$B$4:$BJ$61,MATCH(Both_Shift_Roster!G$2,Morning_Shift!$B$2:$BJ$2,0),0),"")="",IFERROR(VLOOKUP($B7,Evening_Shift!$B$4:$BJ$62,MATCH(Both_Shift_Roster!G$2,Evening_Shift!$B$2:$BJ$2,0),0),""),IFERROR(VLOOKUP($B7,Morning_Shift!$B$4:$BJ$61,MATCH(Both_Shift_Roster!G$2,Morning_Shift!$B$2:$BJ$2,0),0),"")) -> HD | H7: =IF(IFERROR(VLOOKUP($B7,Morning_Shift!$B$4:$BJ$61,MATCH(Both_Shift_Roster!H$2,Morning_Shift!$B$2:$BJ$2,0),0),"")="",IFERROR(VLOOKUP($B7,Evening_Shift!$B$4:$BJ$62,MATCH(Both_Shift_Roster!H$2,Evening_Shift!$B$2:$BJ$2,0),0),""),IFERROR(VLOOKUP($B7,Morning_Shift!$B$4:$BJ$61,MATCH(Both_Shift_Roster!H$2,Morning_Shift!$B$2:$BJ$2,0),0),"")) -> Agent Choice WO | I7: =IF(IFERROR(VLOOKUP($B7,Morning_Shift!$B$4:$BJ$61,MATCH(Both_Shift_Roster!I$2,Morning_Shift!$B$2:$BJ$2,0),0),"")="",IFERROR(VLOOKUP($B7,Evening_Shift!$B$4:$BJ$62,MATCH(Both_Shift_Roster!I$2,Evening_Shift!$B$2:$BJ$2,0),0),""),IFERROR(VLOOKUP($B7,Morning_Shift!$B$4:$BJ$61,MATCH(Both_Shift_Roster!I$2,Morning_Shift!$B$2:$BJ$2,0),0),"")) -> 7:00-14:30 | J7: =IF(IFERROR(VLOOKUP($B7,Morning_Shift!$B$4:$BJ$61,MATCH(Both_Shift_Roster!J$2,Morning_Shift!$B$2:$BJ$2,0),0),"")="",IFERROR(VLOOKUP($B7,Evening_Shift!$B$4:$BJ$62,MATCH(Both_Shift_Roster!J$2,Evening_Shift!$B$2:$BJ$2,0),0),""),IFERROR(VLOOKUP($B7,Morning_Shift!$B$4:$BJ$61,MATCH(Both_Shift_Roster!J$2,Morning_Shift!$B$2:$BJ$2,0),0),"")) -> 7:00-14:30 | K7: =IF(IFERROR(VLOOKUP($B7,Morning_Shift!$B$4:$BJ$61,MATCH(Both_Shift_Roster!K$2,Morning_Shift!$B$2:$BJ$2,0),0),"")="",IFERROR(VLOOKUP($B7,Evening_Shift!$B$4:$BJ$62,MATCH(Both_Shift_Roster!K$2,Evening_Shift!$B$2:$BJ$2,0),0),""),IFERROR(VLOOKUP($B7,Morning_Shift!$B$4:$BJ$61,MATCH(Both_Shift_Roster!K$2,Morning_Shift!$B$2:$BJ$2,0),0),"")) -> 7:00-14:30 | L7: =IF(IFERROR(VLOOKUP($B7,Morning_Shift!$B$4:$BJ$61,MATCH(Both_Shift_Roster!L$2,Morning_Shift!$B$2:$BJ$2,0),0),"")="",IFERROR(VLOOKUP($B7,Evening_Shift!$B$4:$BJ$62,MATCH(Both_Shift_Roster!L$2,Evening_Shift!$B$2:$BJ$2,0),0),""),IFERROR(VLOOKUP($B7,Morning_Shift!$B$4:$BJ$61,MATCH(Both_Shift_Roster!L$2,Morning_Shift!$B$2:$BJ$2,0),0),"")) -> 7:00-14:30 | M7: =IF(IFERROR(VLOOKUP($B7,Morning_Shift!$B$4:$BJ$61,MATCH(Both_Shift_Roster!M$2,Morning_Shift!$B$2:$BJ$2,0),0),"")="",IFERROR(VLOOKUP($B7,Evening_Shift!$B$4:$BJ$62,MATCH(Both_Shift_Roster!M$2,Evening_Shift!$B$2:$BJ$2,0),0),""),IFERROR(VLOOKUP($B7,Morning_Shift!$B$4:$BJ$61,MATCH(Both_Shift_Roster!M$2,Morning_Shift!$B$2:$BJ$2,0),0),"")) -> 7:00-14:30 | N7: =COUNTIF($G7:$M7,"Agent Choice WO") -> 1 | O7: =COUNTIF($G7:$M7,"TL Choice WO") -> 0 | P7: =COUNTIF($G7:$M7,"CL") -> 0 | Q7: =COUNTIF($G7:$M7,"HD") -> 1 | R7: =COUNTIF($G7:$M7,"LP") -> 0 | S7: =IF(IFERROR(VLOOKUP($B7,Morning_Shift!$B$4:$BJ$61,MATCH(Both_Shift_Roster!S$2,Morning_Shift!$B$2:$BJ$2,0),0),"")="",IFERROR(VLOOKUP($B7,Evening_Shift!$B$4:$BJ$62,MATCH(Both_Shift_Roster!S$2,Evening_Shift!$B$2:$BJ$2,0),0),""),IFERROR(VLOOKUP($B7,Morning_Shift!$B$4:$BJ$61,MATCH(Both_Shift_Roster!S$2,Morning_Shift!$B$2:$BJ$2,0),0),"")) -> 7:00-14:30 | T7: =IF(IFERROR(VLOOKUP($B7,Morning_Shift!$B$4:$BJ$61,MATCH(Both_Shift_Roster!T$2,Morning_Shift!$B$2:$BJ$2,0),0),"")="",IFERROR(VLOOKUP($B7,Evening_Shift!$B$4:$BJ$62,MATCH(Both_Shift_Roster!T$2,Evening_Shift!$B$2:$BJ$2,0),0),""),IFERROR(VLOOKUP($B7,Morning_Shift!$B$4:$BJ$61,MATCH(Both_Shift_Roster!T$2,Morning_Shift!$B$2:$BJ$2,0),0),"")) -> 7:00-14:30 | U7: =IF(IFERROR(VLOOKUP($B7,Morning_Shift!$B$4:$BJ$61,MATCH(Both_Shift_Roster!U$2,Morning_Shift!$B$2:$BJ$2,0),0),"")="",IFERROR(VLOOKUP($B7,Evening_Shift!$B$4:$BJ$62,MATCH(Both_Shift_Roster!U$2,Evening_Shift!$B$2:$BJ$2,0),0),""),IFERROR(VLOOKUP($B7,Morning_Shift!$B$4:$BJ$61,MATCH(Both_Shift_Roster!U$2,Morning_Shift!$B$2:$BJ$2,0),0),"")) -> 7:00-14:30 | V7: =IF(IFERROR(VLOOKUP($B7,Morning_Shift!$B$4:$BJ$61,MATCH(Both_Shift_Roster!V$2,Morning_Shift!$B$2:$BJ$2,0),0),"")="",IFERROR(VLOOKUP($B7,Evening_Shift!$B$4:$BJ$62,MATCH(Both_Shift_Roster!V$2,Evening_Shift!$B$2:$BJ$2,0),0),""),IFERROR(VLOOKUP($B7,Morning_Shift!$B$4:$BJ$61,MATCH(Both_Shift_Roster!V$2,Morning_Shift!$B$2:$BJ$2,0),0),"")) -> 7:00-14:30 | W7: =IF(IFERROR(VLOOKUP($B7,Morning_Shift!$B$4:$BJ$61,MATCH(Both_Shift_Roster!W$2,Morning_Shift!$B$2:$BJ$2,0),0),"")="",IFERROR(VLOOKUP($B7,Evening_Shift!$B$4:$BJ$62,MATCH(Both_Shift_Roster!W$2,Evening_Shift!$B$2:$BJ$2,0),0),""),IFERROR(VLOOKUP($B7,Morning_Shift!$B$4:$BJ$61,MATCH(Both_Shift_Roster!W$2,Morning_Shift!$B$2:$BJ$2,0),0),"")) -> 7:00-14:30 | X7: =IF(IFERROR(VLOOKUP($B7,Morning_Shift!$B$4:$BJ$61,MATCH(Both_Shift_Roster!X$2,Morning_Shift!$B$2:$BJ$2,0),0),"")="",IFERROR(VLOOKUP($B7,Evening_Shift!$B$4:$BJ$62,MATCH(Both_Shift_Roster!X$2,Evening_Shift!$B$2:$BJ$2,0),0),""),IFERROR(VLOOKUP($B7,Morning_Shift!$B$4:$BJ$61,MATCH(Both_Shift_Roster!X$2,Morning_Shift!$B$2:$BJ$2,0),0),"")) -> Agent Choice WO | Y7: =IF(IFERROR(VLOOKUP($B7,Morning_Shift!$B$4:$BJ$61,MATCH(Both_Shift_Roster!Y$2,Morning_Shift!$B$2:$BJ$2,0),0),"")="",IFERROR(VLOOKUP($B7,Evening_Shift!$B$4:$BJ$62,MATCH(Both_Shift_Roster!Y$2,Evening_Shift!$B$2:$BJ$2,0),0),""),IFERROR(VLOOKUP($B7,Morning_Shift!$B$4:$BJ$61,MATCH(Both_Shift_Roster!Y$2,Morning_Shift!$B$2:$BJ$2,0),0),"")) -> 7:00-14:30 | Z7: =COUNTIF($S7:$Y7,"Agent Choice WO") -> 1 | AA7: =COUNTIF($S7:$Y7,"TL Choice WO") -> 0 | AB7: =COUNTIF($S7:$Y7,"CL") -> 0 | AC7: =COUNTIF($S7:$Y7,"HD") -> 0 | AD7: =COUNTIF($S7:$Y7,"LP") -> 0 | AE7: =IF(IFERROR(VLOOKUP($B7,Morning_Shift!$B$4:$BJ$61,MATCH(Both_Shift_Roster!AE$2,Morning_Shift!$B$2:$BJ$2,0),0),"")="",IFERROR(VLOOKUP($B7,Evening_Shift!$B$4:$BJ$62,MATCH(Both_Shift_Roster!AE$2,Evening_Shift!$B$2:$BJ$2,0),0),""),IFERROR(VLOOKUP($B7,Morning_Shift!$B$4:$BJ$61,MATCH(Both_Shift_Roster!AE$2,Morning_Shift!$B$2:$BJ$2,0),0),"")) -> 7:00-14:30 | AF7: =IF(IFERROR(VLOOKUP($B7,Morning_Shift!$B$4:$BJ$61,MATCH(Both_Shift_Roster!AF$2,Morning_Shift!$B$2:$BJ$2,0),0),"")="",IFERROR(VLOOKUP($B7,Evening_Shift!$B$4:$BJ$62,MATCH(Both_Shift_Roster!AF$2,Evening_Shift!$B$2:$BJ$2,0),0),""),IFERROR(VLOOKUP($B7,Morning_Shift!$B$4:$BJ$61,MATCH(Both_Shift_Roster!AF$2,Morning_Shift!$B$2:$BJ$2,0),0),"")) -> 7:00-14:30 | AG7: =IF(IFERROR(VLOOKUP($B7,Morning_Shift!$B$4:$BJ$61,MATCH(Both_Shift_Roster!AG$2,Morning_Shift!$B$2:$BJ$2,0),0),"")="",IFERROR(VLOOKUP($B7,Evening_Shift!$B$4:$BJ$62,MATCH(Both_Shift_Roster!AG$2,Evening_Shift!$B$2:$BJ$2,0),0),""),IFERROR(VLOOKUP($B7,Morning_Shift!$B$4:$BJ$61,MATCH(Both_Shift_Roster!AG$2,Morning_Shift!$B$2:$BJ$2,0),0),"")) -> 7:00-14:30 | AH7: =IF(IFERROR(VLOOKUP($B7,Morning_Shift!$B$4:$BJ$61,MATCH(Both_Shift_Roster!AH$2,Morning_Shift!$B$2:$BJ$2,0),0),"")="",IFERROR(VLOOKUP($B7,Evening_Shift!$B$4:$BJ$62,MATCH(Both_Shift_Roster!AH$2,Evening_Shift!$B$2:$BJ$2,0),0),""),IFERROR(VLOOKUP($B7,Morning_Shift!$B$4:$BJ$61,MATCH(Both_Shift_Roster!AH$2,Morning_Shift!$B$2:$BJ$2,0),0),"")) -> 7:00-14:30 | AI7: =IF(IFERROR(VLOOKUP($B7,Morning_Shift!$B$4:$BJ$61,MATCH(Both_Shift_Roster!AI$2,Morning_Shift!$B$2:$BJ$2,0),0),"")="",IFERROR(VLOOKUP($B7,Evening_Shift!$B$4:$BJ$62,MATCH(Both_Shift_Roster!AI$2,Evening_Shift!$B$2:$BJ$2,0),0),""),IFERROR(VLOOKUP($B7,Morning_Shift!$B$4:$BJ$61,MATCH(Both_Shift_Roster!AI$2,Morning_Shift!$B$2:$BJ$2,0),0),"")) -> 7:00-14:30 | AJ7: =IF(IFERROR(VLOOKUP($B7,Morning_Shift!$B$4:$BJ$61,MATCH(Both_Shift_Roster!AJ$2,Morning_Shift!$B$2:$BJ$2,0),0),"")="",IFERROR(VLOOKUP($B7,Evening_Shift!$B$4:$BJ$62,MATCH(Both_Shift_Roster!AJ$2,Evening_Shift!$B$2:$BJ$2,0),0),""),IFERROR(VLOOKUP($B7,Morning_Shift!$B$4:$BJ$61,MATCH(Both_Shift_Roster!AJ$2,Morning_Shift!$B$2:$BJ$2,0),0),"")) -> 7:00-14:30 | AK7: =IF(IFERROR(VLOOKUP($B7,Morning_Shift!$B$4:$BJ$61,MATCH(Both_Shift_Roster!AK$2,Morning_Shift!$B$2:$BJ$2,0),0),"")="",IFERROR(VLOOKUP($B7,Evening_Shift!$B$4:$BJ$62,MATCH(Both_Shift_Roster!AK$2,Evening_Shift!$B$2:$BJ$2,0),0),""),IFERROR(VLOOKUP($B7,Morning_Shift!$B$4:$BJ$61,MATCH(Both_Shift_Roster!AK$2,Morning_Shift!$B$2:$BJ$2,0),0),"")) -> 7:00-14:30 | AL7: =COUNTIF($AE7:$AK7,"Agent Choice WO") -> 0 | AM7: =COUNTIF($AE7:$AK7,"TL Choice WO") -> 0 | AN7: =COUNTIF($AE7:$AK7,"CL") -> 0 | AO7: =COUNTIF($AE7:$AK7,"HD") -> 0 | AP7: =COUNTIF($AE7:$AK7,"LP") -> 0 | AQ7: =IF(IFERROR(VLOOKUP($B7,Morning_Shift!$B$4:$BJ$61,MATCH(Both_Shift_Roster!AQ$2,Morning_Shift!$B$2:$BJ$2,0),0),"")="",IFERROR(VLOOKUP($B7,Evening_Shift!$B$4:$BJ$62,MATCH(Both_Shift_Roster!AQ$2,Evening_Shift!$B$2:$BJ$2,0),0),""),IFERROR(VLOOKUP($B7,Morning_Shift!$B$4:$BJ$61,MATCH(Both_Shift_Roster!AQ$2,Morning_Shift!$B$2:$BJ$2,0),0),"")) -> 7:00-14:30 | AR7: =IF(IFERROR(VLOOKUP($B7,Morning_Shift!$B$4:$BJ$61,MATCH(Both_Shift_Roster!AR$2,Morning_Shift!$B$2:$BJ$2,0),0),"")="",IFERROR(VLOOKUP($B7,Evening_Shift!$B$4:$BJ$62,MATCH(Both_Shift_Roster!AR$2,Evening_Shift!$B$2:$BJ$2,0),0),""),IFERROR(VLOOKUP($B7,Morning_Shift!$B$4:$BJ$61,MATCH(Both_Shift_Roster!AR$2,Morning_Shift!$B$2:$BJ$2,0),0),"")) -> 7:00-14:30 | AS7: =IF(IFERROR(VLOOKUP($B7,Morning_Shift!$B$4:$BJ$61,MATCH(Both_Shift_Roster!AS$2,Morning_Shift!$B$2:$BJ$2,0),0),"")="",IFERROR(VLOOKUP($B7,Evening_Shift!$B$4:$BJ$62,MATCH(Both_Shift_Roster!AS$2,Evening_Shift!$B$2:$BJ$2,0),0),""),IFERROR(VLOOKUP($B7,Morning_Shift!$B$4:$BJ$61,MATCH(Both_Shift_Roster!AS$2,Morning_Shift!$B$2:$BJ$2,0),0),"")) -> 7:00-14:30 | AT7: =IF(IFERROR(VLOOKUP($B7,Morning_Shift!$B$4:$BJ$61,MATCH(Both_Shift_Roster!AT$2,Morning_Shift!$B$2:$BJ$2,0),0),"")="",IFERROR(VLOOKUP($B7,Evening_Shift!$B$4:$BJ$62,MATCH(Both_Shift_Roster!AT$2,Evening_Shift!$B$2:$BJ$2,0),0),""),IFERROR(VLOOKUP($B7,Morning_Shift!$B$4:$BJ$61,MATCH(Both_Shift_Roster!AT$2,Morning_Shift!$B$2:$BJ$2,0),0),"")) -> 7:00-14:30 | AU7: =IF(IFERROR(VLOOKUP($B7,Morning_Shift!$B$4:$BJ$61,MATCH(Both_Shift_Roster!AU$2,Morning_Shift!$B$2:$BJ$2,0),0),"")="",IFERROR(VLOOKUP($B7,Evening_Shift!$B$4:$BJ$62,MATCH(Both_Shift_Roster!AU$2,Evening_Shift!$B$2:$BJ$2,0),0),""),IFERROR(VLOOKUP($B7,Morning_Shift!$B$4:$BJ$61,MATCH(Both_Shift_Roster!AU$2,Morning_Shift!$B$2:$BJ$2,0),0),"")) -> 7:00-14:30 | AV7: =IF(IFERROR(VLOOKUP($B7,Morning_Shift!$B$4:$BJ$61,MATCH(Both_Shift_Roster!AV$2,Morning_Shift!$B$2:$BJ$2,0),0),"")="",IFERROR(VLOOKUP($B7,Evening_Shift!$B$4:$BJ$62,MATCH(Both_Shift_Roster!AV$2,Evening_Shift!$B$2:$BJ$2,0),0),""),IFERROR(VLOOKUP($B7,Morning_Shift!$B$4:$BJ$61,MATCH(Both_Shift_Roster!AV$2,Morning_Shift!$B$2:$BJ$2,0),0),"")) -> Agent Choice WO | AW7: =IF(IFERROR(VLOOKUP($B7,Morning_Shift!$B$4:$BJ$61,MATCH(Both_Shift_Roster!AW$2,Morning_Shift!$B$2:$BJ$2,0),0),"")="",IFERROR(VLOOKUP($B7,Evening_Shift!$B$4:$BJ$62,MATCH(Both_Shift_Roster!AW$2,Evening_Shift!$B$2:$BJ$2,0),0),""),IFERROR(VLOOKUP($B7,Morning_Shift!$B$4:$BJ$61,MATCH(Both_Shift_Roster!AW$2,Morning_Shift!$B$2:$BJ$2,0),0),"")) -> Agent Choice WO | AX7: =COUNTIF($AQ7:$AW7,"Agent Choice WO") -> 2 | AY7: =COUNTIF($AQ7:$AW7,"TL Choice WO") -> 0 | AZ7: =COUNTIF($AQ7:$AW7,"CL") -> 0 | BA7: =COUNTIF($AQ7:$AW7,"HD") -> 0 | BB7: =COUNTIF($AQ7:$AW7,"LP") -> 0 | BC7: =IF(IFERROR(VLOOKUP($B7,Morning_Shift!$B$4:$BJ$61,MATCH(Both_Shift_Roster!BC$2,Morning_Shift!$B$2:$BJ$2,0),0),"")="",IFERROR(VLOOKUP($B7,Evening_Shift!$B$4:$BJ$62,MATCH(Both_Shift_Roster!BC$2,Evening_Shift!$B$2:$BJ$2,0),0),""),IFERROR(VLOOKUP($B7,Morning_Shift!$B$4:$BJ$61,MATCH(Both_Shift_Roster!BC$2,Morning_Shift!$B$2:$BJ$2,0),0),"")) -> 7:00-14:30 | BD7: =IF(IFERROR(VLOOKUP($B7,Morning_Shift!$B$4:$BJ$61,MATCH(Both_Shift_Roster!BD$2,Morning_Shift!$B$2:$BJ$2,0),0),"")="",IFERROR(VLOOKUP($B7,Evening_Shift!$B$4:$BJ$62,MATCH(Both_Shift_Roster!BD$2,Evening_Shift!$B$2:$BJ$2,0),0),""),IFERROR(VLOOKUP($B7,Morning_Shift!$B$4:$BJ$61,MATCH(Both_Shift_Roster!BD$2,Morning_Shift!$B$2:$BJ$2,0),0),"")) -> 7:00-14:30 | BE7: =IF(IFERROR(VLOOKUP($B7,Morning_Shift!$B$4:$BJ$61,MATCH(Both_Shift_Roster!BE$2,Morning_Shift!$B$2:$BJ$2,0),0),"")="",IFERROR(VLOOKUP($B7,Evening_Shift!$B$4:$BJ$59,MATCH(Both_Shift_Roster!BE$2,Evening_Shift!$B$2:$BJ$2,0),0),""),IFERROR(VLOOKUP($B7,Morning_Shift!$B$4:$BJ$61,MATCH(Both_Shift_Roster!BE$2,Morning_Shift!$B$2:$BJ$2,0),0),"")) -> 7:00-14:30 | BF7: =COUNTIF($BC7:$BE7,"Agent Choice WO") -> 0 | BG7: =COUNTIF($BC7:$BE7,"TL Choice WO") -> 0 | BH7: =COUNTIF($BC7:$BE7,"CL") -> 0 | BI7: =COUNTIF($BC7:$BE7,"HD") -> 0 | BJ7: =COUNTIF($BC7:$BE7,"LP") -> 0
